Workbook

Sheet (과제 승인 후)2.실행과제LIST

Sheet 1.아이디어LIST
A1: ○ 아이디어LIST | AB1: 변경전 | AD1: 구 분 | AE1: 본 사 | AF1: 현 장 | AG1: 전체 | AJ1: 변경후 | AK1: 구분 | AL1: 건축 | AM1: 개발 | AN1: 인프라 | AO1: 지원 | AP1: 전체 | AR1: 건축 | AS1: 개발 | AT1: 인프라 | AU1: 지원 | AV1: 전체
AK2: 보정 | AL2: 4 | AN2: 2 | AO2: 7 | AP2: 13 | AR2: 보정 사유 : 아이디어 제안서 접수 없이 중점과제 진행
AD3: 접수 | AE3: 620 | AF3: 1072 | AG3: 1692 | AK3: 접수 | AL3: 1175 | AM3: 160 | AN3: 194 | AO3: 175 | AP3: 1704 | AR3: FALSE | AS3: FALSE | AT3: T | AU3: FALSE | AV3: FALSE
A4: - 문서 목적: 1. 아이디어 내용 정리(보고 자료 및 데이터 사용 필요), 2. 아이디어 제안, 채택 포상 지급, 3. 불인정, 불채택 건에 대한 피드백, 4. 업무 그레이존 방지(담당자 명확화, 접수 후 진행상황 점검) | AD4: (불인정) | AE4: 111 | AF4: 315 | AG4: 426 | AK4: (불인정) | AL4: 325 | AM4: 32 | AN4: 39 | AO4: 30 | AP4: 426
AD5: 인정 검토 중 | AE5: 0 | AF5: 0 | AG5: 0 | AK5: 인정 검토중 | AL5: 0 | AM5: 0 | AN5: 0 | AO5: 0 | AP5: 0
D6: 아이디어 접수자, 작성 | H6: 검토 후 담당자, 작성 | AD6: 인정 | AE6: 503 | AF6: 754 | AG6: 1257 | AK6: 인정 | AL6: 843 | AM6: 127 | AN6: 155 | AO6: 144 | AP6: 1269 | AR6: T | AS6: T | AT6: T | AU6: T | AV6: T
AD7: (불상정) | AE7: 375 | AF7: 696 | AG7: 1071 | AK7: (불상정) | AL7: 727 | AM7: 116 | AN7: 130 | AO7: 98 | AP7: 1071
A8: NO | B8: Code | C8: 제안자 | I8: 제안일 | J8: TOP추진실 담당자 | K8: 담당자 | L8: 아이디어 제안 요약 | Q8: 검토 | V8: 주요 일정 관리 | X8: 포상 시기 | AA8: 비고 | AB8: 0 | AD8: 상정 검토 중 | AE8: 33 | AF8: 24 | AG8: 57 | AK8: 상정 검토 중 | AL8: =COUNTIFS($Q:$Q,"검토중",$C:$C,"건축") -> 8 | AM8: =COUNTIFS($Q:$Q,"검토중",$C:$C,"개발") -> 0 | AN8: =COUNTIFS($Q:$Q,"검토중",$C:$C,"인프라") -> 3 | AO8: {=+SUM(COUNTIFS($Q:$Q,"검토중",$C:$C,{"인사지원","기획실","기획","안전환경","직속부서","직속","법무실"}))} -> 2 | AP8: =SUM(AL8:AO8) -> 13
C9: 본부 | D9: 사업장 | E9: 사번 | F9: 직급 | G9: 소속 | H9: 성명 | I9: 제안일 | J9: (참고) 검토담당 | K9: 1차 검토 담당자 | L9: 대분류 | M9: 중분류 | N9: 소분류 | O9: 제안 제목 | P9: 제안 내용 상세 | Q9: 제안 인정 | R9: 채택 현황 | S9: 인정 점수 | T9: 채택 점수 | U9: 검토 의견 및 제안자 피드백 | V9: CFT구성 여부 | W9: 과제승인위원회 상정 여부 | X9: 제안 인정 | Y9: 채택 포상 | Z9: 피드백 완료 여부 | AB9: 중복 | AD9: 승인위(예정) | AE9: 80 | AF9: 25 | AG9: 105 | AK9: 승인위(예정) | AL9: =+COUNTIFS($R:$R,"o",$C:$C,"건축")+4 -> 84 | AM9: =+COUNTIFS($R:$R,"o",$C:$C,"개발") -> 4 | AN9: =+COUNTIFS($R:$R,"o",$C:$C,"인프라")+2 -> 12 | AO9: {=SUM(COUNTIFS($R:$R,"O",$C:$C,{"인사지원","기획실","기획","안전환경","외주구매","직속부서","직속","법무실"}))+7} -> 36 | AP9: =SUM(AL9:AO9) -> 136
AD10: 실행 | AE10: 0 | AF10: 0 | AG10: 0 | AK10: 실행 | AL10: 59 | AM10: 2 | AN10: 5 | AO10: 28 | AP10: 94
A11: 1 | B11: PR/P-M-CE-1 | C11: 건축 | D11: 현장 | E11: 2102486 | F11: 대리 | G11: 춘천 프리미엄 빌리지 건설공사 | H11: 황준하 | I11: 45474 | J11: 박재보, 박병규, | K11: 박재보 | L11: 구매 | M11: 기계 | N11: 공사비 | O11: (지급자재 전환) 욕실휀 지급자재 전환 및 연간단가 체결 | P11: • 욕실휀 연간단가로 지정하여 지급자재로 전환 시 재료비 절감 효과 기대. 공동주택 세대 수가 많을수록 절감효과가 클 것으로 예상(ex 온도조절기) | Q11: O | R11: O | S11: 28 | T11: 82 | V11: O | W11: 3차(240909) | X11: 24년3분기(240920) | Y11: 24년3분기(240920) | Z11: Case4. (채택)피드백 완료 | AD11: 목요일 오전 8시 기준 주간 업무일정 작성예정 | AL11: 건축 | AM11: 개발 | AN11: 인프라 | AO11: 지원 | AP11: 합계
A12: 2 | B12: CO/Z-ID/A-CE-1 | C12: 건축 | D12: 본사 | E12: 2000173 | F12: 대리 | G12: TOP추진실 | H12: 최재형 | I12: 45474 | J12: 차원재, 양창모, 차원재 | K12: 박재보 | M12: 보험료 | N12: 공사비 | O12: 산재보험료 산출 정확도 향상을 통한 원가추정 ↑ | P12: • (유형효과) 절감 예상 금액 = 납품성 공종 금액x30%(노무비율) x2.66% (추정 집행 요율) • (투자비) 원가코드 개선을 위한 프로그래밍비용 • (과제수행 기간) 24년 08월 ~25년 07월(12달) • (기타) 납품성 자재비(MEP장비납품 등)의 금액이 큰 현장의 경우 해당금액이 산재보험료 집행 모수에 반영되어 산재보험료 금액 상승 | Q12: O | R12: X | S12: 20 | T12: 68 | U12: 손익에 영향이 없는 내용. 다만, 회사의 투입(IT시스템 개발+매월 관리 인력) 대비 내부 원가관리의 원활/정확성을 위해 추진할 것인가에 대해서는 논의하였으나 현재는 필요성이 낮고 담당자가 매월 모든 계약 건을 확인하여야 되서 현실적으로 업무가 더 늘어남. 매월 고용산재 전사 금액(3월 년납 선급처리 후 1/12을 매월 원가 처리)을 본사/각 현장의 (직접인건비+간접인건비(외주/자재비*노무비율30%))*고용산재요율)를 기준으로 분배되어 본사/각 현장으로 원가투입이 됨. 특정현장이 실재 고용산재 납부시, 포함되지 않은 항목이 원가 배분시 투입되면 그 현장의 원가가 늘어나지만 타 현장의 원가는 줄어듬. 전사로 보면 동일함. | X12: 24년3분기(240920) | Z12: Case2. (인정O,채택X)피드백 완료 | AL12: 13
A13: 3 | B13: CO/I-TF-CE-1 | C13: 건축 | D13: 본사 | E13: 1907086 | F13: 대리 | G13: 건축견적팀 | H13: 조윤재 | I13: 45474 | J13: 양창모, 박준용, 양창모 | K13: 양창모 | L13: 수행-비공사성 | M13: 공통가설 | N13: 공사비 | O13: 폐기물 처리비 투입기준 최신화, 혼폐 체적당 계약 및 집게차 운영을 통한 부피축소 | P13: • (유형효과) 24년 실행대비 5% 절감, 25년 실행대비 6% 절감 • (투자비) 1,500만원(=집게차 임대료 250만원x6개월) [VAT 제외] • (과제수행 기간) 24년 08월 ~25년 08월(12달) • (기타) 실행편성 기준 현실화(혼폐, m3당 단가 적용), 현장 분리수거 강화 노력 | Q13: O | R13: O | S13: 25 | T13: 71 | V13: O | W13: 7차(250114) | X13: 24년3분기(240920) | Y13: 25년1분기(000000) | Z13: Case3. (인정O,채택 검토)피드백 완료 | AL13: 62 | AO13: 45
A14: 4 | B14: EN/EX-A/F-CE-1 | C14: 건축 | D14: 본사 | E14: 1103501 | F14: 차장 | G14: 건축견적팀 | H14: 정관희 | I14: 45474 | J14: 김태용, 송원일, 김태용 | K14: 김태용 | L14: 설계_건축외부 | M14: 건축_마감 | N14: 공사비 | O14: 공동주택 외벽마감재 석재 → 세라믹타일 | P14: • 석재 대체 자재 발굴 및 적용 - 상품성을 저해하지 않으면서 석재의 역할을 대신할 수 있는 자재 발굴 및 적용 - 기술혁신파트너몰 (https://partner.lh.or.kr/promote/view.asp)에 등재된 외장타일 적용 여부 검토 필요 - 경량(10T) 자재이며 등재된 단가 25,000원/M2로 시공성과 원가 절감 가능 - 인건비 절감 효과 클 것으로 기대 (협력사 인터뷰 및 견적수취로 추후 효과검증) - 시공사례 적어 현장 견학 필요 (춘천 파밀리에 리버파크_신동아건설) | Q14: O | R14: X | S14: 18 | T14: 58 | U14: (1차검토 : 미채택) 포레나2.0은 단일석종 100%적용 중이며 해당석종(오련회) 자재단가는 20,000원 초중반/M2 수준으로 제안자재의 유의미한 절감 효과 없음 | X14: 24년3분기(240920) | Z14: Case2. (인정O,채택X)피드백 완료 | AL14: 1106 | AO14: 181
A15: 5 | B15: EN/I-A/F-CE-1 | C15: 건축 | D15: 본사 | E15: 2202075 | F15: 과장 | G15: 건축견적팀 | H15: 임정근 | I15: 45474 | J15: 김태용, 송원일, 김태용 | K15: 김태용 | L15: 설계_건축내부 | M15: 건축_마감 | N15: 공사비 | O15: 욕실 골조벽면 액체방수 삭제 | P15: 욕실 벽체중 콘크리트면의 액체방수 설계제외 (단, 조적벽과 만나는 코너부위 도막방수보강등은 유지) | Q15: O | R15: X | S15: 21 | T15: 67 | U15: (1차검토 : 미채택) '23년 외주 SE 2기 기 시행사항 | X15: 24년3분기(240920) | Z15: Case2. (인정O,채택X)피드백 완료 | AK15: 아이디어 제안 | AL15: =COUNTIFS($C:$C,"건축") -> 1310 | AM15: =COUNTIFS($C:$C,"개발") -> 164 | AN15: =COUNTIFS($C:$C,"인프라") -> 250 | AO15: =1850-SUM(AL15:AN15) -> 126
A16: 6 | B16: EN/I-A/F-CE-2 | C16: 건축 | D16: 본사 | E16: 2200403 | F16: 대리 | G16: 건축견적팀 | H16: 이현지 | I16: 45474 | J16: 김태용, 송원일, 김태용 | K16: 김태용 | L16: 설계_건축내부 | M16: 건축_마감 | N16: 공사비 | O16: 현관 타일 사이즈 변경 600*600 → 300*300 | P16: • 현관창고는 수납의 공간으로 당사의 경우 현관과 동일한 타일 적용 | Q16: O | R16: X | S16: 24 | T16: 통합 (186번) | U16: (1차검토 : 타 과제와 통합) | X16: 24년3분기(240920) | Z16: Case2. (인정O,채택X)피드백 완료 | AA16: 통합 (186번) | AK16: 과제화 진행 | AL16: 82 | AM16: 4 | AN16: 12 | AO16: 36
A17: 7 | B17: PR/P-M-CE-2 | C17: 건축 | D17: 본사 | E17: 2201216 | F17: 대리 | G17: 건축견적팀 | H17: 이현준 | I17: 45474 | J17: 박재보, 박병규, | K17: 박재보 | L17: 구매 | M17: 기계 | N17: 공사비 | O17: (지급자재 전환) 외주계약 휀류(Ex. 지하 유인휀) → 구매자재 변경 | P17: - 현재 유인휀은 기계설비공사(외주공사) 내 자재비+노무비로 편성되어 있음 - 기계설비업체 입찰 단가에 의해 유인휀 단가 편차가 생김 | Q17: O | R17: O | S17: 26 | T17: 82 | V17: O | W17: 3차(240909) | X17: 24년3분기(240920) | Y17: 24년3분기(240920) | Z17: Case4. (채택)피드백 완료 | AF17: 지난주 | AG17: 1114 | AH17: 144 | AI17: 162 | AJ17: 168 | AK17: 1588 | AL17: <<여기부터 갱신
A18: 8 | B18: EN/E-E-CE-1 | C18: 건축 | D18: 본사 | E18: 1700070 | F18: 대리 | G18: 건축견적팀 | H18: 이상준 | I18: 45474 | J18: 오정화, 오정화, | K18: 오정화 | L18: 설계_전기 | M18: 전기 | N18: 공사비 | O18: 강제전선관 타입변경 (후강전선관→나사없는 전선관) | P18: • 나사없는전선관 사용시 나사산이 없는 방식의 연결로 배관을 보다 쉽고 빠르게 체결 가능 (볼트식 이음쇠 및 부속품 사용) • 후강전선관 대비 경량으로 취급이 용이하여 시공성 향상에 의한 노무비 절감 가능 | Q18: O | R18: O | S18: 25 | T18: 87 | V18: O | W18: 3차(240909) | X18: 24년3분기(240920) | Y18: 24년3분기(240920) | Z18: Case4. (채택)피드백 완료 | AF18: 금주 | AG18: 1175 | AH18: 160 | AI18: 194 | AJ18: 175 | AK18: 1704
A19: 9 | B19: CO/I-TF-CE-2 | C19: 건축 | D19: 현장 | E19: 0703047 | F19: 차장 | G19: 창원IDC 신축공사 | H19: 윤재만 | I19: 45474 | J19: 양창모, 박준용, 양창모 | K19: 박병규 | L19: 수행-비공사성 | M19: 공통가설 | N19: 공사비 | O19: 간이소화장치 재사용 (준공현장 자재 타현장 재사용) | P19: • 기존 현장의 준공 이전 가설 해체 시점에 간이소화장치 이동식 및 고정식을 신규 현장으로 이관하여 재설치 활용이 가능하고, 해당 현장 실행 편성 시 적용 여부에 따른 실행 감액 편성을 통한 원가 절감 가능 | Q19: O | R19: X | S19: 20 | T19: 68 | U19: 재사용 아이디어는 좋으나, 과거 유사한 형태로 진행되었던 사례를 봤을때, 현장에서 기존제품 관리 및 재사용화(제품화)가 어려워 전문업체를 통한 리사이클이 효과적이라 생각됨 | X19: 24년3분기(240920) | Z19: Case2. (인정O,채택X)피드백 완료 | AF19: 신규접수 | AG19: 61 | AH19: 16 | AI19: 32 | AJ19: 7 | AK19: 116
A20: 10 | B20: EN/E-E-CE-2 | C20: 건축 | D20: 본사 | E20: 0700716 | F20: 차장 | G20: 건축견적팀 | H20: 송인홍 | I20: 45474 | J20: 오정화, 오정화, | K20: 오정화 | L20: 설계_전기 | M20: 전기 | N20: 공사비 | O20: 무인택배시설 삭제 | P20: • 무인택배설비의 사용성 저하로 인해 FORENA 기본설계에서 삭제를 검토하고 별도로 건축심의 또는 조합(발주처)의 요구, LH/SH 심의의견 등에 따라서 선별 적용하는 기준으로 변경하는 것을 검토하고자 함 | Q20: O | R20: X | S20: 21 | T20: 63 | U20: 일괄 삭제 또는 최적화(수량 최소화)와 관련하여 사업팀 협의가 필요한 제안임. 추후 재검토 예정 | X20: 24년3분기(240920) | Z20: Case2. (인정O,채택X)피드백 완료 | AG20: 건축 | AH20: 개발 | AI20: 인프라 | AJ20: 지원 | AK20: 합계
A21: 11 | B21: EN/M-M-CE-1 | C21: 건축 | D21: 본사 | E21: 2203377 | F21: 과장 | G21: 건축견적팀 | H21: 송성무 | I21: 45474 | J21: 박병규, 박병규, | K21: 박병규 | L21: 설계_기계 | M21: 기계 | N21: 공사비 | O21: 공동주택 세대 수도계량기함 동파방지열선 변경 | P21: • [공동주택 개선방안] : 세대 계량기 양수기함內 동파방지용 전기열선 일부층 보온솜으로 변경 - 지상1~2층, 최상층 : 양수기함(스티로폼) + 동파방지용 전기열선(1M) - 지상3층 ~ 최상층의 직하층 : 양수기함(스티로폼) + 보온솜  동파 우려가 적은 층(지상3층~최상층의 직하층) 열선 삭제, 보온솜으로 대체 | Q21: O | R21: O | S21: 19 | T21: 80 | U21: 타사 사례 및 건축기계팀과 검토하여 15차 승인위원회 과제화 예정 | V21: O | W21: 15차(251104) | X21: 24년3분기(240920) | Y21: 25년3,4분기(251209) | Z21: Case2. (인정O,채택X)피드백 완료
A22: 12 | B22: CO/I-TF-CE-3 | C22: 건축 | D22: 해외 | E22: 0600067 | F22: 차장 | G22: 건축지원팀(파견) | H22: 성정각 | I22: 45474 | J22: 양창모, 박준용, 양창모 | K22: 박병규 | L22: 수행-비공사성 | M22: 공통가설 | N22: 공사비 | O22: 준공현장 소화기 타현장 이관 | P22: • 프로세스를 정립하여 준공현장의 소화기를 필요한 현장으로 이관 각현장 별 소방안전관리자 취합 -> 현장 관리팀 건축지원팀 보고후 이관 -> 이관현장은 이관물량 제외 발주 | Q22: O | R22: X | S22: 20 | T22: 68 | U22: 재사용 아이디어는 좋으나, 과거 유사한 형태로 진행되었던 사례를 봤을때, 현장에서 기존제품 관리 및 재사용화(제품화)가 어려워 전문업체를 통한 리사이클이 효과적이라 생각됨 | X22: 24년3분기(240920) | Z22: Case2. (인정O,채택X)피드백 완료
A23: 13 | B23: CO/D-A/F-CE-1 | C23: 건축 | D23: 본사 | E23: 2203417 | F23: 과장 | G23: 건축견적팀 | H23: 박민석 | I23: 45474 | J23: 안희진, 송원일, 김태용 | K23: 안희진 | L23: 수행-공사성 | M23: 건축_마감 | N23: 공사비 | O23: 현관문 보양지 준공청소 제거 → 입주자 직접제거로 변환 | P23: • 상위 타 건설사는 근래 방화문 보양지를 입주 후 입주자가 제거하게 하여 원인미상 하자를 미연에 방지. (타공종 긁힘 하자 등) • 세대현관문 설치 후 디지털도어락 설치 전까지 간이 도어핸들 또는 도어체크를 즉시 설치하여 바람 등의 의한 충격 파손 하자를 방지하여 AS원가 절감. | Q23: X | S23: 14 | U23: 현재에도 입주자 직접 제거분으로 처리하는 현장이 있습니다. 공사팀 관계자의 의사결정을 통해 결정할 수 있는 사항이어서 아이디어로 채택되지 않았습니다. | Z23: Case1. (인정X)피드백 완료
A24: 14 | B24: EN/S-C-CE-1 | C24: 건축 | D24: 본사 | E24: 1500183 | F24: 과장 | G24: 건축견적팀 | H24: 김태경 | I24: 45474 | J24: 박준용, 박준용, 양창모 | K24: 박준용 | L24: 구조/토목 | M24: 토목 | N24: 공사비 | O24: 흙막이 ↔ 외벽간 너비를 감안한 설계로 투입비용 절감 | P24: • 합벽-흙막이 간격 축소 방안 검토(Case별 축소 방안마련) • 각종 심의 후 흙막이 Line 변경은 어려우므로 심의전 설계검토하여 흙막이 Line 최적화 실시 | Q24: O | R24: X | S24: 18 | T24: 69 | U24: 아이디어 인정, 과제 미채택 유관부서(기술혁신팀, 건축견적팀) 협의 통하여 비합벽 이격치수 확정 및 공유에 대한 필요성이 있습니다. | X24: 24년3분기(240920) | Z24: Case2. (인정O,채택X)피드백 완료
A25: 15 | B25: EN/I-A/F-CE-3 | C25: 건축 | D25: 본사 | E25: 1500183 | F25: 과장 | G25: 건축견적팀 | H25: 김태경 | I25: 45474 | J25: 김태용, 송원일, 김태용 | K25: 김태용 | L25: 설계_건축내부 | M25: 건축_마감 | N25: 공사비 | O25: 상가 바닥마감 기준 변경 비닐계타일 → 무근 | P25: • 상가 바닥 마감변경(무근+비닐계타일 → 무근 마감) - 분양시, 상가바닥 마감은 무근 마감임을 사전에 공지 • 상가 벽, 천정 마감도 사전에 마감 진행여부 확인 및 서명을 받아 삭제가 가능하다면 삭제 - 벽, 천정마감도 개별인테리어 실시로 마감을 원치 않은 계약자 발생 • 기타시설(지식산업센터, 업무시설) 등에도 점차 확대 적용 | Q25: X | S25: 14 | U25: (1차검토 : 미채택) 순수 분양형 근생 및 판매시설에 적용할 가능성이 있는 제한적 아이디어로, 발주처(시행사, 조합 등)와 협의 진행 시 마감 제외 외 별도 추가 요청이 빈번하여 오히려 현장 실행에 부담 줄 가능성이 높음 | Z25: Case1. (인정X)피드백 완료
A26: 16 | B26: CO/I-TF-CE-4 | C26: 건축 | D26: 본사 | E26: 1803688 | F26: 대리 | G26: 건축견적팀 | H26: 김주상 | I26: 45474 | J26: 양창모, 박준용, 양창모 | K26: 양창모 | L26: 수행-비공사성 | M26: 공통가설 | N26: 공사비 | O26: 승강기 설치전 E.V홀 또는 외부 윈치 설치하여 양중 및 하역 | P26: • 엘리베이터 설치 전 엘리베이터 통로 또는 발코니 외부에 윈치를 설치하여 양중 및 하역 진행 | Q26: O | R26: X | S26: 22 | T26: 50 | U26: 아이디어가 참신하여 아이디어 제안 인정되나, 안전에 대한 심층적 검토가 필요하여 미채택 | X26: 24년3분기(240920) | Z26: Case2. (인정O,채택X)피드백 완료
A27: 17 | B27: EN/EX-A/F-CE-2 | C27: 건축 | D27: 본사 | E27: 1000198 | F27: 차장 | G27: 건축견적팀 | H27: 구민정 | I27: 45474 | J27: 김태용, 송원일, 김태용 | K27: 김태용 | L27: 설계_건축외부 | M27: 건축_마감 | N27: 공사비 | O27: 공동주택 저층부 석재마감 최소화 | P27: • 지상1층(입주민의 접촉 구간)은 석재50%수준으로 적용하고, 지상2~3층 및 단차부(옹벽 등) 주1을 및 근생부 외벽은 석재뿜칠 적용하여 원가 경쟁력 확보 • 분양성 저해의 소지는 있으나, 심의 전 변경이 가능한 경우 적용 확대 • 조경 특화의 사례처럼 포레나 외부 특화 아이템을 별도로 만들어 준공시점 설계변경으로 도급 증액 유도 | Q27: O | R27: X | S27: 19 | T27: 65 | U27: (1차검토 : 미채택) 포레나2.0은 단일석종 100%적용 중이며 해당석종(오련회) 자재단가는 20,000원 초중반/M2 수준으로 제안자재의 유의미한 절감 효과 없음 | X27: 24년3분기(240920) | Z27: Case2. (인정O,채택X)피드백 완료
A28: 18 | B28: EN/I-A/S-CE-1 | C28: 건축 | D28: 본사 | E28: 1000198 | F28: 차장 | G28: 건축견적팀 | H28: 구민정 | I28: 45474 | J28: 김태용, 송원일, 박준용 | K28: 김태용 | L28: 설계_건축내부 | M28: 건축_골조 | N28: 공사비 | O28: PIT 최소화를 통한 원가율 개선 | P28: • 충주 용산 현장의 사례처럼 세대창고로 활용하거나, 포레나 지하 특화아이템을 개발 • 마감 공사가 단순한 수준 - 단위 세대별 지하 창고 - 악기 연주 (드럼, 색소폰 등) 소음이 커서 집에서 하기 어려운 취미 활동 공간 | Q28: O | R28: X | S28: 18 | T28: 64 | U28: (1차검토 : 미채택) 지하 PIT 적용할 공간 아이템이 직접 제시되지 못 함 | X28: 24년3분기(240920) | Z28: Case2. (인정O,채택X)피드백 완료
A29: 19 | B29: EN/I-A/F-CE-4 | C29: 건축 | D29: 본사 | E29: 1000198 | F29: 차장 | G29: 건축견적팀 | H29: 구민정 | I29: 45474 | J29: 김태용, 송원일, 김태용 | K29: 김태용 | L29: 설계_건축내부 | M29: 건축_마감 | N29: 공사비 | O29: 대림 이앤씨 평면 벤치마킹 및 무상제공 품목 조정 | P29: • 대림이앤씨 평면 적용으로 절감 가능한 사항 (84이상 타입 기준) - 확장시 안방 발코니 삭제 등 평면 조정 1. 안방부위: 분합창, 대피구간 SD 1개소, 조적벽량 삭제 2. 알파룸 WD 1개 및 주방팬트리도어 1개 삭제 - 무상제공 삭제 1. 팬트리 시스템선반 (ㄷ → ㅡ) 변경 2. 욕실 하1갑 옵션 판매 (당사 카운터탑 무상제공), 발코니 세탁선반 삭제 (당사 무상제공) • 검토 제외 사항 1. 골조 벽량 (향후, 기술팀/기계/전기팀과 협업 필요) | Q29: O | R29: X | S29: 24 | T29: 통합 (중점) | U29: (1차검토 : 중점과제와 통합) 타사 평면들을 참조하여 절감형 포레나 평면 개발이 중점과제로 진행되고 있습니다. 아이디어로 인정되나 과제진행은 중점과제로 병합되어 진행될 예정입니다. | X29: 24년3분기(240920) | Z29: Case2. (인정O,채택X)피드백 완료
A30: 20 | B30: EN/E-E-CE-3 | C30: 건축 | D30: 본사 | E30: 2202060 | F30: 대리 | G30: 건축견적팀 | H30: 강대구 | I30: 45474 | J30: 오정화, 오정화, | K30: 오정화 | L30: 설계_전기 | M30: 전기 | N30: 공사비 | O30: EPS실 콘센트 삭제 | P30: • 아파트 EPS실 각종 전원 콘센트로 유지관리 콘센트 겸용 가능 • 타사 GS건설 EPS실 유지관리 콘센트 미설계 | Q30: O | R30: X | S30: 18 | T30: 62 | U30: 마감공사작업시 공사용 전원으로 유용하다는 현장의견이 많음. 공동주택의 경우 대부분 EPS/TPS 겸용으로 통신장비 예비 전원용으로도 활용가능 (ISP, 이동통신 등) | X30: 24년3분기(240920) | Z30: Case2. (인정O,채택X)피드백 완료
A31: 21 | B31: EN/S-A/S-CE-1 | C31: 외주구매 | D31: 본사 | E31: 1907089 | F31: 대리 | G31: 구매팀 | H31: 권효준 | I31: 45474 | J31: 박준용, 송원일, 박준용 | K31: 박준용 | L31: 구조/토목 | M31: 건축_골조 | N31: 공사비 | O31: D22 이하 기둥 철근 이음 시 B급이음 → A급이음 적용 | P31: • D22 이하 기둥 철근 이음 시 A급이음 적용 | Q31: O | R31: X | S31: 18 | U31: 아이디어 인정, 과제 미채택(통합) 해당내용(A급이음 -> 압축이음)을 적용하기 위해서는 원구조설계사의 별도 검토가 필요함(용역비 발생할 수 있음), 기술혁신팀 과제화중이며 현장 누락없이 적용가능한 프로세스를 마련중입니다. | X31: 24년3분기(240920) | Z31: Case2. (인정O,채택X)피드백 완료 | AA31: 통합 (40번)
A32: 22 | B32: CO/Z-PI-EXP-1 | C32: 건축 | D32: 본사 | E32: 0700706 | F32: 차장 | G32: 건축지원팀 | H32: 김필중 | I32: 45474 | J32: 차원재, 박재보, 고한울 | K32: 박재보 | L32: 공통 | M32: 프로세스 개선 | N32: 전사경비 | O32: 벽걸이 달력 미지급 | P32: • 대달력 전 직원 미제공 또는 최소 필요 수량 제공 또는 현장(팀)별 50% 제공 - 효과 발생시 계열사 확대 시행 | Q32: O | R32: X | S32: 20 | T32: 통합 (180번) | X32: 24년3분기(240920) | Z32: Case2. (인정O,채택X)피드백 완료
A33: 23 | B33: CO/I-TF-CE-5 | C33: 건축 | D33: 본사 | E33: 0700706 | F33: 차장 | G33: 건축지원팀 | H33: 김필중 | I33: 45474 | J33: 양창모, 박준용, 양창모 | K33: 오정화 | L33: 수행-비공사성 | M33: 공통가설 | N33: 공사비 | O33: 협력사 가설전기 사용료 부담 | P33: • 협력사 계량기 설치 및 가설전기 사용료 개별 부담에 따른 전력 감소 및 전기사용료 절감 | Q33: O | R33: X | S33: 24 | T33: 통합 (266번) | U33: 266번 제안과 통합 | X33: 24년3분기(240920) | Z33: Case2. (인정O,채택X)피드백 완료
A34: 24 | B34: CO/Z-PI-CE-1 | C34: 건축 | D34: 본사 | E34: 1104096 | F34: 과장 | G34: 건축지원팀 | H34: 문성호 | I34: 45474 | J34: 차원재, 박재보, 고한울 | K34: 박재보 | L34: 공통 | M34: 프로세스 개선 | N34: 공사비 | O34: [단기목표] 중고거래 APP개발을 통한 자재현황관리 및 공유 [중장기목표] 건축자재중고거래 e-커머스 사업(ex : 당근 플랫폼) | P34: [단기목표] ▪ 개선전 : 현장 잉여공사자재 및 가설자재, 사무실 집기류 등 관리 소홀에 따른 손실 ▪ 개선후 : APP(ex : 당근 플랫폼)을 통한 실시간 전현장 자재 현황 파악 가능하여 현장 대 현장 공유를 통해 신규 구입 방지 및 긴급 필요 자재 공유하여 현장 원가 리스크 감소 (협력사도 참여) [중장기목표] ▪ e-커머스 사업을 통해 타건설사 및 협력업체까지 공유하는 방식의 건축자재중고거래 를 통해 마켓쉐어 될 수 있는 중고거래시장 개척 (이익창출 및 브랜드 가치 상승_재사용을 통한 ESG 경영과도 부합) | Q34: O | R34: X | S34: 23 | T34: 56 | U34: 방향성, 아이디어는 좋으나 논의 결과 개발비 및 투입 인력 등 회사의 역량 부족. 현실적으로 어려움 | X34: 24년3분기(240920) | Z34: Case2. (인정O,채택X)피드백 완료
A35: 25 | B35: PR/P-TF-CE-1 | C35: 건축 | D35: 본사 | E35: 1502614 | F35: 과장 | G35: 건축지원팀 | H35: 민경민 | I35: 45474 | J35: 박재보, 박준용, 양창모 | K35: 박재보 | L35: 구매 | M35: 공통가설 | N35: 공사비 | O35: 동절기보양자재 지급자재 → 철콘업체 지입자재로 전환 | P35: • 철콘업체 지입자재로 입찰 진행 | Q35: X | S35: 14 | U35: 과거 지입자재에서 지급자재로 변경된 품목임. 건설경기 활황시, 수급문제와 철콘업체의 과도한 단가 요구 및 비위 문제로 지급자재로 운영중임. 과거 논의가 많이 되었던 건으로 아이디어로 인정하기 어려움 | Z35: Case1. (인정X)피드백 완료
A36: 26 | B36: CO/Z-PI-CE-2 | C36: 건축 | D36: 현장 | E36: 1502615 | F36: 과장 | G36: 원당1구역 재개발 | H36: 민승기 | I36: 45474 | J36: 차원재, 박재보, 고한울 | K36: 박재보 | L36: 공통 | M36: 프로세스 개선 | N36: 공사비 | O36: 착준공지원팀 신설로 착준공 지원 | P36: • (준공)‘24년 6개 / ‘25년 9개 / ‘26년 7개 준공 Risk 최소화 • (착공) 향후 수주 PJ 착수 지원 | Q36: X | S36: 12 | U36: 최근까지 수차례 논의 되었던 사안. 아이디어 제공자의 소속팀의 고유업무. 새로운 TOP아이디어로 인정되기 어려움 | Z36: Case1. (인정X)피드백 완료
A37: 27 | B37: CO/Z-PI-EXP-2 | C37: 건축 | D37: 본사 | E37: 1203784 | F37: 사원 | G37: 건축지원팀 | H37: 안혜림 | I37: 45474 | J37: 차원재, 박재보, 고한울 | K37: 박재보 | L37: 공통 | M37: 프로세스 개선 | N37: 전사경비 | O37: 캘린더, 다이어리 종류별 개별 신청 | P37: • 업무시스템 - 임직원공통 – 이벤트신청 메뉴를 활용한 개별신청으로, 현장 및 부서별 신청수량 조정이나 별도 취합이 필요 없음 | Q37: O | R37: X | S37: 20 | T37: 통합 (180번) | X37: 24년3분기(240920) | Z37: Case2. (인정O,채택X)피드백 완료
A38: 28 | B38: CO/Z-PI-EXP-3 | C38: 건축 | D38: 본사 | E38: 1300816 | F38: 과장 | G38: 외주팀 | H38: 이승현 | I38: 45474 | J38: 차원재, 박재보, 고한울 | K38: 박재보 | L38: 공통 | M38: 프로세스 개선 | N38: 전사경비 | O38: 노트북 3년 이상 사용으로 원가절감시, 렌탈비용 50%에 상응하는 복지포인트 지급 | P38: • 평소 노트북 관리를 통해 조기 렌탈 사용료 발생 방지 • 노트북 신청 주기 관리를 통한 원가 절감 달성시 렌탈 비용 50%에 상응 하는 복지포인트 지급 | Q38: X | S38: 9 | U38: 현재 렌탈로 운영되어 사용주기 초과하여도 원가절감 효과가 없음. 현황 파악이 잘 못되어 아이디어로 인정 어려움 | Z38: Case1. (인정X)피드백 완료
A39: 29 | B39: PR/C-PI-CE-1 | C39: 건축 | D39: 본사 | E39: 2202025 | F39: 차장 | G39: 건축지원팀 | H39: 이철호 | I39: 45474 | J39: 고한울, 박재보, 고한울 | K39: 고한울 | L39: 외주 | M39: 프로세스 개선 | N39: 공사비 | O39: 준공후 협력업체 정산프로세스 수립 | P39: • 준공 +1개월 : 협력업체 정산 계획 현황 서면 보고 • 준공 +2개월 : 미정산 협력업체 정산 협의 현황 및 계획 서면 보고 • 준공 +3개월 : 미정산 협력업체 정산 계획 사업부 대면 보고 (현장소장, 공사팀장, 공무팀장) → 필요시 협력업체 담당자 / 현장 / 유관부서(건축지원,외주外) 본사 회의 실시 현장설명서에 협력업체 정산 요청 방법 및 기한 관련 기준 추가 삽입 | Q39: O | R39: O | S39: 23 | T39: 통합 | U39: 하도급법 강화에 따른 협력사 정산 지연시 지연이자가 발생하여 당사 영영이익 감소에 큰 영향을 주고 있는 사안입니다. 프로세스 개선 및 업무 혁신을 통한 지연이자 최소화를 달성해야 합니다. 협력사와의 계약, 현장의 원가관리, 사업부 사업관리 등 많은 유관부서와의 연관성이 있는바, CFT 를 구성하여 종합적인 활동을 이끌어야 됩니다. | W39: N차(미정) | X39: 24년3분기(240920) | Z39: Case3. (인정O,채택 검토)피드백 완료 | AA39: 정산 프로세스 및 지연이자에 대한 검토사항입니다. (29번, 72번, 80번 유사함)
A40: 30 | B40: CO/D-A/F-CS-1 | C40: 건축 | D40: 본사 | E40: 0600053 | F40: 차장 | G40: 건축지원팀 | H40: 임양순 | I40: 45474 | J40: 안희진, 송원일, 김태용 | K40: 안희진 | L40: 수행-공사성 | M40: 건축_마감 | N40: 하자보수 | O40: 타일 뒷채움 부족 및 부착강도 하자소송비 저감 추진 | P40: • 외주(타일공사)공사 현장설명서 개정, “뒷채움 기준”, “피해에 대한 보상", “부착강도 기준” 등 • 외주(타일공사)공사 내역에 “타일 뒷채움 조사비”, “부착강도 시험비” 항목 신설 • 현장별 자료 보존 및 소송 時 활용 | Q40: O | R40: X | S40: 20 | T40: 통합 | X40: 24년3분기(240920) | Z40: Case2. (인정O,채택X)피드백 완료
...

Sheet (참고)재직자
A1: 사번 | B1: 성명 | C1: 본부 | D1: 소속 | E1: 사업장 | F1: 직급 | G1: 직무 | H1: 구분 | R1: 본부 | S1: 본부 | T1: 소속 | U1: 제안건수
A2: 9207446 | B2: 김우석 | C2: 직속부서 | D2: 대표이사 | E2: 본사 | F2: 사장 | G2: 경영 | H2: 일반직 | R2: 직속부서 | T2: 경영전략실 | U2: =COUNTIFS('1.아이디어LIST'!$G$11:G1037,'(참고)재직자'!T2) -> 0
A3: 9623972 | B3: 박철광 | C3: 인사지원 | D3: 인사기획팀 | E3: 본사 | F3: 임원 | G3: 경영 | H3: 일반직 | T3: 감사팀 | U3: =COUNTIFS('1.아이디어LIST'!$G$11:G1038,'(참고)재직자'!T3) -> 0
A4: 0011256 | B4: 김민석 | C4: 건축 | D4: 건축사업본부장 | E4: 본사 | F4: 임원 | G4: 경영기획 | H4: 일반직 | T4: TOP추진실 | U4: =COUNTIFS('1.아이디어LIST'!$G$11:G1039,'(참고)재직자'!T4) -> 1
A5: 0301116 | B5: 이준명 | C5: 인프라 | D5: 인프라사업본부장 | E5: 본사 | F5: 임원 | G5: 경영 | H5: 일반직 | T5: 계 | U5: =SUM(U2:U4) -> 1
A6: 0010846 | B6: 여성진 | C6: 인사지원 | D6: 인사기획팀 | E6: 본사 | F6: 임원 | G6: 경영 | H6: 일반직 | R6: 기획실 | T6: 기획팀 | U6: =COUNTIFS('1.아이디어LIST'!$G$11:G1041,'(참고)재직자'!T6) -> 2
A7: 9606450 | B7: 이종훈 | C7: 인사지원 | D7: 인사기획팀 | E7: 본사 | F7: 임원 | G7: 사업관리 | H7: 일반직 | T7: 투자전략팀 | U7: =COUNTIFS('1.아이디어LIST'!$G$11:G1042,'(참고)재직자'!T7) -> 3
A8: 0110760 | B8: 김형준 | C8: 인사지원 | D8: 커뮤니케이션담당 | E8: 본사 | F8: 임원 | G8: 홍보 | H8: 일반직 | T8: 기획관리팀 | U8: =COUNTIFS('1.아이디어LIST'!$G$11:G1043,'(참고)재직자'!T8) -> 0
A9: 0702370 | B9: 윤성호 | C9: 개발 | D9: 개발사업본부장 | E9: 본사 | F9: 임원 | G9: 경영 | H9: 일반직 | T9: 내부회계운영팀 | U9: =COUNTIFS('1.아이디어LIST'!$G$11:G1044,'(참고)재직자'!T9) -> 2
A10: 0011259 | B10: 장우성 | C10: 개발 | D10: 전략사업실장 | E10: 본사 | F10: 임원 | G10: 건설영업 | H10: 일반직 | T10: 원가효율화팀 | U10: =COUNTIFS('1.아이디어LIST'!$G$11:G1045,'(참고)재직자'!T10) -> 0
A11: 0110914 | B11: 오용근 | C11: 기획 | D11: 기획실장 | E11: 본사 | F11: 임원 | G11: 경영 | H11: 일반직 | T11: DT팀 | U11: =COUNTIFS('1.아이디어LIST'!$G$11:G1046,'(참고)재직자'!T11) -> 3
A12: 0200581 | B12: 임진규 | C12: 외주구매 | D12: 외주구매실장 | E12: 본사 | F12: 임원 | G12: 경영기획 | H12: 일반직 | T12: 계 | U12: =SUM(U6:U11) -> 10
A13: 0201016 | B13: 정윤상 | C13: 건축 | D13: CS실장 | E13: 본사 | F13: 임원 | G13: 품질 | H13: 일반직 | R13: 법무실 | T13: 법무팀 | U13: =COUNTIFS('1.아이디어LIST'!$G$11:G1048,'(참고)재직자'!T13) -> 0
A14: 0300616 | B14: 박영재 | C14: 해외 | D14: 이라크사업실장 | E14: 해외 | F14: 임원 | G14: 경영 | H14: 일반직 | T14: 계 | U14: =U13 -> 0
A15: 0500077 | B15: 이정수 | C15: 인프라 | D15: 수행혁신실장 | E15: 본사 | F15: 임원 | G15: 사업관리 | H15: 일반직 | R15: 안전환경경영실 | T15: 안전보건기획팀 | U15: =COUNTIFS('1.아이디어LIST'!$G$11:G1050,'(참고)재직자'!T15) -> 0
A16: 0500681 | B16: 황율남 | C16: 개발 | D16: 개발사업실장 | E16: 본사 | F16: 임원 | G16: 건설영업 | H16: 일반직 | T16: 안전보건운영팀 | U16: =COUNTIFS('1.아이디어LIST'!$G$11:G1051,'(참고)재직자'!T16) -> 1
A17: 0500765 | B17: 김주돈 | C17: 인프라 | D17: 토목사업실장 | E17: 본사 | F17: 임원 | G17: 건설영업 | H17: 일반직 | T17: 환경지원팀 | U17: =COUNTIFS('1.아이디어LIST'!$G$11:G1052,'(참고)재직자'!T17) -> 0
A18: 0903441 | B18: 전창수 | C18: 인사지원 | D18: 인사지원실장 | E18: 본사 | F18: 임원 | G18: 경영 | H18: 일반직 | T18: 계 | U18: =SUM(U15:U17) -> 1
A19: 9710188 | B19: 송태을 | C19: 인프라 | D19: 환경사업실장 | E19: 본사 | F19: 임원 | G19: 건설영업 | H19: 일반직 | R19: 경영지원본부 | S19: 인사지원실 | T19: 인사기획팀 | U19: =COUNTIFS('1.아이디어LIST'!$G$11:G1054,'(참고)재직자'!T19) -> 1
A20: 9711103 | B20: 박광호 | C20: 건축 | D20: 건축지원실장 | E20: 본사 | F20: 임원 | G20: 사업관리 | H20: 일반직 | T20: 인사운영팀 | U20: =COUNTIFS('1.아이디어LIST'!$G$11:G1055,'(참고)재직자'!T20) -> 0
A21: 0900062 | B21: 김태형 | C21: 인사지원 | D21: 인사기획팀 | E21: 본사 | F21: 임원 | G21: 법무 | H21: 일반직 | T21: 현장지원팀 | U21: =COUNTIFS('1.아이디어LIST'!$G$11:G1056,'(참고)재직자'!T21) -> 3
A22: 0010487 | B22: 김윤석 | C22: 인프라 | D22: 환경사업PD | E22: 본사 | F22: 임원 | G22: 건설영업 | H22: 일반직 | T22: 홍보팀 | U22: =COUNTIFS('1.아이디어LIST'!$G$11:G1057,'(참고)재직자'!T22) -> 0
A23: 0300506 | B23: 차상민 | C23: 건축 | D23: 경상/제주PD | E23: 본사 | F23: 임원 | G23: 사업관리 | H23: 일반직 | T23: CR지원팀 | U23: =COUNTIFS('1.아이디어LIST'!$G$11:G1058,'(참고)재직자'!T23) -> 0
A24: 0300507 | B24: 송재형 | C24: 건축 | D24: 서울역세권PD | E24: 본사 | F24: 임원 | G24: 사업관리 | H24: 일반직 | S24: 외주구매실 | T24: 외주상생혁신팀 | U24: =COUNTIFS('1.아이디어LIST'!$G$11:G1059,'(참고)재직자'!T24) -> 2
A25: 0500782 | B25: 최은국 | C25: 건축 | D25: 충청/전라PD | E25: 본사 | F25: 임원 | G25: 사업관리 | H25: 일반직 | T25: 외주팀 | U25: =COUNTIFS('1.아이디어LIST'!$G$11:G1060,'(참고)재직자'!T25) -> 11
A26: 9606623 | B26: 김창복 | C26: 건축 | D26: 서울/경기북부PD | E26: 본사 | F26: 임원 | G26: 사업관리 | H26: 일반직 | T26: 구매팀 | U26: =COUNTIFS('1.아이디어LIST'!$G$11:G1061,'(참고)재직자'!T26) -> 7
A27: 9623751 | B27: 황인성 | C27: 인프라 | D27: 토목사업PD | E27: 본사 | F27: 임원 | G27: 시공 | H27: 일반직 | T27: 계 | U27: =SUM(U19:U26) -> 24
A28: 9710346 | B28: 송도화 | C28: 건축 | D28: 경기남부/강원PD | E28: 본사 | F28: 임원 | G28: 사업관리 | H28: 일반직 | R28: 개발사업본부 | T28: 개발기획팀 | U28: =COUNTIFS('1.아이디어LIST'!$G$11:G1063,'(참고)재직자'!T28) -> 0
A29: 0201023 | B29: 김윤해 | C29: 안전환경 | D29: 안전환경경영실장(CSO) | E29: 본사 | F29: 임원 | G29: ESH | H29: 일반직 | T29: 마케팅팀 | U29: =COUNTIFS('1.아이디어LIST'!$G$11:G1064,'(참고)재직자'!T29) -> 0
A30: 0800028 | B30: 강진혁 | C30: 개발 | D30: 마케팅팀 | E30: 본사 | F30: 임원 | G30: 주택마케팅 | H30: 일반직 | T30: 마케팅팀(사업소) | U30: =COUNTIFS('1.아이디어LIST'!$G$11:G1065,'(참고)재직자'!T30) -> 1
A31: 0400915 | B31: 김성수 | C31: 인사지원 | D31: 인사기획팀 | E31: 본사 | F31: 임원 | G31: 사업관리 | H31: 일반직 | T31: 전략사업팀 | U31: =COUNTIFS('1.아이디어LIST'!$G$11:G1066,'(참고)재직자'!T31) -> 0
A32: 9606413 | B32: 이은원 | C32: 인사지원 | D32: 인사기획팀 | E32: 본사 | F32: 임원 | G32: 사업관리 | H32: 일반직 | T32: 개발사업팀 | U32: =COUNTIFS('1.아이디어LIST'!$G$11:G1067,'(참고)재직자'!T32) -> 11
A33: 9624731 | B33: 최원균 | C33: 인사지원 | D33: 인사기획팀 | E33: 본사 | F33: 임원 | G33: 경영 | H33: 일반직 | T33: 개발사업팀(사업소) | U33: =COUNTIFS('1.아이디어LIST'!$G$11:G1068,'(참고)재직자'!T33) -> 1
A34: 9604733 | B34: 최광호 | C34: 인사지원 | D34: 임원실 | E34: 본사 | F34: 고문 | G34: 경영 | H34: 일반직 | T34: 건축영업팀 | U34: =COUNTIFS('1.아이디어LIST'!$G$11:G1069,'(참고)재직자'!T34) -> 10
A35: 0010692 | B35: 한상범 | C35: 건축 | D35: 서울아레나 복합문화시설 | E35: 현장 | F35: 부장 | G35: 시공 | H35: 일반직 | T35: 주택사업팀 | U35: =COUNTIFS('1.아이디어LIST'!$G$11:G1070,'(참고)재직자'!T35) -> 6
A36: 0200563 | B36: 박홍진 | C36: 건축 | D36: 아산배방 생활숙박시설 | E36: 현장 | F36: 부장 | G36: 시공 | H36: 일반직 | T36: 정비사업팀 | U36: =COUNTIFS('1.아이디어LIST'!$G$11:G1071,'(참고)재직자'!T36) -> 3
A37: 0300598 | B37: 이광준 | C37: 건축 | D37: 운암3단지 재건축 | E37: 현장 | F37: 부장 | G37: 시공 | H37: 일반직 | T37: 정비사업팀(사업소) | U37: =COUNTIFS('1.아이디어LIST'!$G$11:G1072,'(참고)재직자'!T37) -> 4
A38: 0300619 | B38: 황광섭 | C38: 건축 | D38: 창원IDC 신축공사 | E38: 현장 | F38: 부장 | G38: 시공 | H38: 일반직 | T38: 마켓솔루션TFT | U38: =COUNTIFS('1.아이디어LIST'!$G$11:G1073,'(참고)재직자'!T38) -> 0
A39: 0301111 | B39: 송원일 | C39: 건축 | D39: 고양 삼송 이지스 데이터센터 | E39: 현장 | F39: 부장 | G39: 시공 | H39: 일반직 | S39: 건축사업부 | T39: 건축지원팀 | U39: =COUNTIFS('1.아이디어LIST'!$G$11:G1074,'(참고)재직자'!T39) -> 22
A40: 0500425 | B40: 김재원 | C40: 건축 | D40: 대전 학하 민간임대 | E40: 현장 | F40: 부장 | G40: 시공 | H40: 일반직 | T40: 기술혁신팀 | U40: =COUNTIFS('1.아이디어LIST'!$G$11:G1075,'(참고)재직자'!T40) -> 44
...

Sheet SPC(재직자)_250829 기준
A1: 0400584 | B1: 조동성 | C1: 개발 | D1: ㈜에이치씨앤디 | E1: 현장 | F1: 부장 | G1: 1갑
A2: 2203986 | B2: 정예헌 | C2: 개발 | D2: ㈜에이치씨앤디 | E2: 현장 | F2: 차장 | G2: 1을
A3: 1202926 | B3: 이동건 | C3: 개발 | D3: ㈜에이치씨앤디 | E3: 현장 | F3: 과장 | G3: 2갑
A4: 2203990 | B4: 송영도 | C4: 개발 | D4: ㈜에이치씨앤디 | E4: 현장 | F4: 과장 | G4: 2갑
A5: 1100749 | B5: 박명기 | C5: 개발 | D5: ㈜에이치씨앤디 | E5: 현장 | F5: 과장 | G5: 2갑
A6: 2203989 | B6: 전유림 | C6: 개발 | D6: ㈜에이치씨앤디 | E6: 현장 | F6: 과장 | G6: 2갑
A7: 2203992 | B7: 서정석 | C7: 개발 | D7: ㈜에이치씨앤디 | E7: 현장 | F7: 대리 | G7: 2을
A8: 2203993 | B8: 김윤중 | C8: 개발 | D8: ㈜에이치씨앤디 | E8: 현장 | F8: 대리 | G8: 2을
A9: 2302350 | B9: 김민경 | C9: 개발 | D9: ㈜에이치씨앤디 | E9: 현장 | F9: 사무직4급 | G9: 사무직4급
A10: 9606995 | B10: 임홍구 | C10: 개발 | D10: (주)수서역환승센터복합개발 | E10: 현장 | F10: 부장 | G10: 1갑
A11: 1106425 | B11: 이명휘 | C11: 개발 | D11: (주)수서역환승센터복합개발 | E11: 현장 | F11: 차장 | G11: 1을
A12: 1000556 | B12: 한승연 | C12: 개발 | D12: (주)수서역환승센터복합개발 | E12: 현장 | F12: 차장 | G12: 1을
... A25: 1890016 | B25: 송현주 | C25: 개발 | D25: ㈜서울역북부역세권개발 | E25: 현장 | F25: 사무직(무기) | G25: 사무직(무기)
B31: 유한진 | D31: 전배 (건설 주택사업팀)
B32: 최병규 | D32: 전배 (솔루션 인사이트)
B33: 강영록 | D33: 전배 (건설 전략사업1팀)
B34: 윤성민 | D34: 전배 (솔루션 인사이트)
B35: 정화용 | D35: 전배 (한화인베스트먼트)
B36: 최보윤 | D36: 전배 (솔루션 인사이트)

Sheet Code
A1: 코드 구분
A2: 대분류 | B2: 코드 | C2: 중분류 | D2: 코드 | E2: 소분류 | F2: 코드 | I2: 인정, 채택 구분값
A3: 구조/토목 | B3: EN/S | C3: 건축_골조 | D3: A/S | E3: 공사비 | F3: CE | I3: O | M3: 포상 완료 여부 | N3: 중복 여부 | T3: CFT구성 | U3: 과제 승인 위원회
A4: 설계_건축외부 | B4: EN/EX | C4: 건축_마감 | D4: A/F | E4: 사업비 | F4: BE | I4: X | M4: Case1. (인정X)피드백 완료 | N4: O | T4: O | U4: 1차(240822)
A5: 설계_건축내부 | B5: EN/I | C5: 토목 | D5: C | E5: 하자보수 | F5: CS | I5: 검토중 | M5: Case2. (인정O,채택X)피드백 완료 | T5: O | U5: 2차(240829)
A6: 설계_기계 | B6: EN/M | C6: 전기 | D6: E | E6: 분양 | F6: SA | M6: Case3. (인정O,채택 검토)피드백 완료 | T6: O | U6: 3차(240909)
A7: 설계_전기 | B7: EN/E | C7: 조경 | D7: L | E7: 판관비 | F7: SNA | M7: Case4. (채택)피드백 완료 | T7: O | U7: 4차(241016)
A8: 외주 | B8: PR/C | C8: 기계 | D8: M | E8: 전사경비 | F8: EXP | U8: 5차(241104)
A9: 구매 | B9: PR/P | C9: 기타공종 | D9: Z | P9: EN/S | U9: 6차(241203)
A10: 수행-공사성 | B10: CO/D | C10: 공통가설 | D10: TF | P10: EN/EX | U10: 7차(250114)
A11: 수행-비공사성 | B11: CO/I | C11: 현장관리비 | D11: YY | P11: EN/I | U11: 8차(250219)
A12: 공통 | B12: CO/Z | C12: 보험료 | D12: ID/A | P12: EN/M | U12: 9차(250327)
A13: 인프라 | B13: IN/C | C13: 안전관리비 | D13: ID/H | P13: EN/E | U13: 10차(250423)
A14: 개발/영업 | B14: D/PM | C14: 환경관리비 | D14: ID/P | P14: PR/C | T14: 지급일자 | U14: 11차(250526)
C15: 민원처리비 | D15: ID/R | P15: PR/P | T15: 24년3분기(240920) | U15: 12차(250623)
C16: 기타경비 | D16: ID/Z | P16: CO/D | T16: 24년4분기(241220) | U16: 13차(250825)
C17: 프로세스 개선 | D17: PI | P17: CO/I | T17: 25년1분기(250421) | U17: 14차(250929)
P18: CO/Z | T18: 25년2분기(250721) | U18: 15차(251104)
A19: 1차 담당자 | E19: (참고)공통 담당자 | M19: 건축_골조 | N19: 고한울 | P19: 구조 | Q19: 박준용 | T19: 25년3,4분기(251209) | U19: 16차(251219)
A20: 대분류 | B20: 코드 | C20: 1차 담당자 | E20: 중분류 | F20: 코드 | G20: 공통1 | H20: 공통2 | M20: 건축_마감 | N20: 안희진 | P20: 설계 | Q20: 김태용
A21: 구조/토목 | B21: EN/S | C21: 박준용 | E21: 건축_골조 | F21: A/S | G21: 고한울 | H21: 박준용 | I21: 공사비 | J21: CE | M21: 토목 | N21: 박준용 | P21: 외주 | Q21: 고한울
A22: 설계_건축외부 | B22: EN/EX | C22: 김태용 | E22: 건축_마감 | F22: A/F | G22: 고한울 | H22: 김태용 | I22: 사업비 | J22: BE | M22: 전기 | N22: 오정화 | P22: 구매 | Q22: 박재보 | U22: N차(미정)
A23: 설계_건축내부 | B23: EN/I | C23: 김태용 | E23: 토목 | F23: C | G23: 박준용 | I23: 하자보수 | J23: CS | M23: 조경 | N23: 김태용 | P23: 수행
A24: 설계_기계 | B24: EN/M | C24: 박병규 | E24: 전기 | F24: E | G24: 오정화 | I24: 분양 | J24: SA | M24: 기계 | N24: 박병규 | P24: 공통 | Q24: 박재보
A25: 설계_전기 | B25: EN/E | C25: 오정화 | E25: 조경 | F25: L | G25: 김태용 | I25: 판관비 | J25: SNA | M25: 기타공종 | N25: 박준용
A26: 외주 | B26: PR/C | C26: 고한울 | E26: 기계 | F26: M | G26: 박병규 | I26: 전사경비 | J26: EXP | M26: 공통가설 | N26: 박준용
A27: 구매 | B27: PR/P | C27: 박재보 | E27: 기타공종 | F27: Z | G27: 박준용 | M27: 현장관리비 | N27: 박재보
A28: 수행-공사성 | B28: CO/D | C28: 고한울 | E28: 공통가설 | F28: TF | G28: 박준용 | M28: 보험료 | N28: 박재보
A29: 수행-비공사성 | B29: CO/I | C29: 박재보 | E29: 현장관리비 | F29: YY | G29: 박재보 | M29: 안전관리비 | N29: 박재보
A30: 공통 | B30: CO/Z | C30: 박재보 | E30: 보험료 | F30: ID/A | G30: 박재보 | M30: 환경관리비 | N30: 최재형
A31: 인프라 | B31: IN/C | C31: 김태영 | E31: 안전관리비 | F31: ID/H | G31: 박재보 | M31: 민원처리비 | N31: 박재보
A32: 개발/영업 | B32: D/PM | C32: 박명진 | E32: 환경관리비 | F32: ID/P | G32: 최재형 | M32: 기타경비 | N32: 박재보
C33: 최성록 | E33: 민원처리비 | F33: ID/R | G33: 박재보 | M33: 프로세스 개선 | N33: 박재보
E34: 기타경비 | F34: ID/Z | G34: 박재보
E35: 프로세스 개선 | F35: PI | G35: 박재보
